<robot name="simplebot">
  <!-- link -->
    <link name="base_link">
    </link>

    <link name="wheel_left_link">
      <visual>
        <geometry>
          <mesh filename="package://simplebot_description/dae/wheel.dae" />
          <!-- <cylinder length="0.025" radius="0.0325"/> -->
        </geometry>
        <origin xyz="0 0 0" rpy="0 0 3.14"/>
          <material name="red">
          <!-- <color rgba="1.0 0.0 0.0 1.0"/> -->
        </material>

      </visual>
      <collision>
        <geometry>
          <cylinder length="0.025" radius="0.0325"/>
        </geometry>
        <origin xyz="0.0275 0 0" rpy="0 1.57 0"/>
      </collision>
      <inertial>
        <origin xyz="0 0 0" rpy="0 0 0"/>
        <mass value="0.05"/>
        <inertia ixx="0.000015807" ixy="0" ixz="0"
          iyy="0.000015807" iyz="0"
          izz="0.000026406"/>
      </inertial>
    </link>

    <link name="wheel_right_link">
      <visual>
        <geometry>
          <mesh filename="package://simplebot_description/dae/wheel.dae" />
          <!-- <cylinder length="0.025" radius="0.0325"/> -->
        </geometry>
        <origin xyz="0 0 0" rpy="0 0 0"/>
          <material name="red">
          <!-- <color rgba="1.0 0.0 0.0 1.0"/> -->
        </material>

      </visual>
      <collision>
        <geometry>
          <cylinder length="0.025" radius="0.0325"/>
        </geometry>
        <origin xyz="-0.0275 0 0" rpy="0 1.57 0"/>
      </collision>
      <inertial>
        <origin xyz="0 0 0" rpy="0 0 0"/>
        <mass value="0.05"/>
        <inertia ixx="0.000015807" ixy="0" ixz="0"
          iyy="0.000015807" iyz="0"
          izz="0.000026406"/>
      </inertial>
    </link>

    <link name="motor_left_link">
      <visual>
        <geometry>
          <mesh filename="package://simplebot_description/dae/motor.dae" />
          <!-- <cylinder length="0.06" radius="0.02"/> -->
        </geometry>
        <origin xyz="0 0 0" rpy="0 0 0"/>
          <material name="red">
          <!-- <color rgba="1.0 0.0 0.0 1.0"/> -->
        </material>

      </visual>
      <collision>
        <geometry>
          <cylinder length="0.06" radius="0.02"/>
        </geometry>
        <origin xyz="0 -0.03 0.025" rpy="0 1.57 1.57"/>
      </collision>
      <inertial>
        <origin xyz="0 0 0" rpy="0 0 0"/>
        <mass value="0.3"/>
        <inertia ixx="0.000136875" ixy="0" ixz="0"
          iyy="0.000136875" iyz="0"
          izz="0.00006"/>
      </inertial>
    </link>

    <link name="motor_right_link">
      <visual>
        <geometry>
          <mesh filename="package://simplebot_description/dae/motor.dae" />
          <!-- <cylinder length="0.06" radius="0.02"/> -->
        </geometry>
        <origin xyz="0 0 0" rpy="0 0 0"/>
          <material name="red">
          <!-- <color rgba="1.0 0.0 0.0 1.0"/> -->
        </material>

      </visual>
      <collision>
        <geometry>
          <cylinder length="0.06" radius="0.02"/>
        </geometry>
        <origin xyz="0 -0.03 0.025" rpy="0 1.57 1.57"/>
      </collision>
      <inertial>
        <origin xyz="0 0 0" rpy="0 0 0"/>
        <mass value="0.3"/>
        <inertia ixx="0.000136875" ixy="0" ixz="0"
          iyy="0.000136875" iyz="0"
          izz="0.00006"/>
      </inertial>
    </link>

    <link name="body_link">
      <visual>
        <geometry>
          <mesh filename="package://simplebot_description/dae/base_board.dae" />
          <!-- <box size="0.21 0.297 0.004"/> -->
        </geometry>
          <material name="red">
          <!-- <color rgba="1.0 0.0 0.0 1.0"/> -->
        </material>
      </visual>
      <collision>
        <geometry>
          <box size="0.21 0.297 0.004"/>
        </geometry>
        <origin xyz="0 0 0" rpy="0 0 0"/>
      </collision>
      <inertial>
        <origin xyz="0 0 0" rpy="0 0 0"/>
        <mass value="0.3"/>
        <inertia ixx="0.0011029" ixy="0" ixz="0"
          iyy="0.002205625" iyz="0"
          izz="0.003307725"/>

          <!-- <inertia ixx="1.0" ixy="0" ixz="0"
          iyy="1.0" iyz="0"
          izz="1.0"/> -->
      </inertial>
    </link>

    <!-- caster -->

    <link name="caster_holder_link">
      <visual>
        <geometry>
          <cylinder length="0.04" radius="0.02"/>
        </geometry>
          <material name="red">
          <!-- <color rgba="1.0 0.0 0.0 1.0"/> -->
        </material>
      </visual>

      <collision>
        <geometry>
          <cylinder length="0.04" radius="0.02"/>
        </geometry>
      </collision>
      
    <inertial>
      <origin xyz="0 0 0"/>
      <mass value="0.05"/>
      <inertia ixx="0.000011666" ixy="0" ixz="0" iyy="0.000011666"  iyz="0" izz="0.000011666"/>
    </inertial>

    </link>

    <link name="caster_ball_link">
      <visual>
        <geometry>
          <sphere radius="0.015"/>
        </geometry>
        <material name="green">
          <color rgba="0 1 0 1"/>
        </material>
      </visual>

      <collision>
        <geometry>
          <sphere radius="0.015"/>
        </geometry>
      </collision>
      
    <inertial>
      <origin xyz="0 0 0"/>
      <mass value="0.05"/>
      <inertia ixx="0.0000045" ixy="0" ixz="0" iyy="0.0000045"  iyz="0" izz="0.0000045"/>
    </inertial>

    </link>

    <!-- joint -->
    <joint name="base_joint" type="fixed">
        <parent link="base_link"/>
        <child  link="body_link"/>
        <origin xyz="0 0 0.0535" rpy="0 0 -1.57"/>
    </joint>

    <joint name="motor_left_joint" type="fixed">
        <parent link="body_link"/>
        <child  link="motor_left_link"/>
        <origin xyz="-0.105 0.13 -0.004" rpy="0 3.14 1.57"/>
    </joint>
    <joint name="wheel_left_joint" type="continuous">
        <parent link="motor_left_link"/>
        <child  link="wheel_left_link"/>
        <origin xyz="0 0 0.025" rpy="0 0 1.57"/>
    </joint>

    <joint name="motor_right_joint" type="fixed">
        <parent link="body_link"/>
        <child  link="motor_right_link"/>
        <origin xyz="0.105 0.13 -0.004" rpy="0 3.14 -1.57"/>
    </joint>
    <joint name="wheel_right_joint" type="continuous">
        <parent link="motor_right_link"/>
        <child  link="wheel_right_link"/>
        <origin xyz="0 0 0.025" rpy="0 0 -1.57"/>
    </joint>

    <!-- caster -->
    <joint name="caster_holder_joint" type="fixed">
      <parent link="body_link"/>
      <child  link="caster_holder_link"/>
      <origin xyz="0 -0.12 -0.02" rpy="0 0 1.57"/>
    </joint>
    <joint name="caster_ball_joint" type="fixed">
      <parent link="caster_holder_link"/>
      <child  link="caster_ball_link"/>
      <origin xyz="0 0 -0.025" rpy="0 0 1.57"/>
    </joint>

    
    <gazebo reference="wheel_right_link">
      <selfCollide>true</selfCollide>
      <mu1 value="0.75" />
      <mu2 value="0.75" />
    </gazebo>

    <gazebo reference="wheel_left_link">
      <selfCollide>true</selfCollide>
      <mu1 value="0.75" />
      <mu2 value="0.75" />
    </gazebo>

    <gazebo reference="body_link">
      <selfCollide>true</selfCollide>
      <mu1 value="0.08" />
      <mu2 value="0.08" />
    </gazebo>

    <gazebo reference="caster_ball_link">
      <selfCollide>true</selfCollide>
      <mu1 value="0.0" />
      <mu2 value="0.0" />
    </gazebo>


  </robot>
